<?xml version="1.0" encoding="utf-8"?>
<!-- This URDF was automatically created by SolidWorks to URDF Exporter! Originally created by Stephen Brawner (brawner@gmail.com) 
     Commit Version: 1.5.1-0-g916b5db  Build Version: 1.5.7152.31018
     For more information, please see http://wiki.ros.org/sw_urdf_exporter -->
<robot
  name="lide">
  <link
    name="base_link">
    <inertial>
      <origin
        xyz="-0.128036162467698 0.0849000506865905 0.0505742338532695"
        rpy="0 0 0" />
      <mass
        value="2.92032891635219" />
      <inertia
        ixx="0.00623119457208926"
        ixy="-6.06137450802783E-07"
        ixz="-1.19575978629178E-05"
        iyy="0.00559464379591167"
        iyz="-3.44724488787282E-07"
        izz="0.0111645591761783" />
    </inertial>
    <visual>
      <origin
        xyz="0 0 0"
        rpy="0 0 0" />
      <geometry>
        <mesh
          filename="package://lide/meshes/base_link.STL" />
      </geometry>
      <material
        name="">
        <color
          rgba="0.752941176470588 0.752941176470588 0.752941176470588 1" />
      </material>
    </visual>
    <collision>
      <origin
        xyz="0 0 0"
        rpy="0 0 0" />
      <geometry>
        <mesh
          filename="package://lide/meshes/base_link.STL" />
      </geometry>
    </collision>
  </link>
  <link
    name="LFS">
    <inertial>
      <origin
        xyz="0.0455604268709419 0.00830943309140332 0.00297622851896683"
        rpy="0 0 0" />
      <mass
        value="0.0727928435161986" />
      <inertia
        ixx="2.20927876796312E-05"
        ixy="-1.64845302056301E-08"
        ixz="-1.5645477317522E-07"
        iyy="1.62632133784213E-05"
        iyz="2.96411876511233E-09"
        izz="1.80843397531752E-05" />
    </inertial>
    <visual>
      <origin
        xyz="0 0 0"
        rpy="0 0 0" />
      <geometry>
        <mesh
          filename="package://lide/meshes/LFS.STL" />
      </geometry>
      <material
        name="">
        <color
          rgba="0.752941176470588 0.752941176470588 0.752941176470588 1" />
      </material>
    </visual>
    <collision>
      <origin
        xyz="0 0 0"
        rpy="0 0 0" />
      <geometry>
        <mesh
          filename="package://lide/meshes/LFS.STL" />
      </geometry>
    </collision>
  </link>
  <joint
    name="LFS"
    type="fixed">
    <origin
      xyz="-0.059044 0.1674 -0.036503"
      rpy="1.5708 0 1.5708" />
    <parent
      link="base_link" />
    <child
      link="LFS" />
    <axis
      xyz="0 0 0" />
  </joint>
  <link
    name="LFW">
    <inertial>
      <origin
        xyz="0.015 -6.93889390390723E-18 0"
        rpy="0 0 0" />
      <mass
        value="0.767080911081153" />
      <inertia
        ixx="0.00116426102407189"
        ixy="-1.25105048588131E-22"
        ixz="-1.83311841364852E-20"
        iyy="0.000639661580367031"
        iyz="-6.7762635780344E-21"
        izz="0.000639661580367032" />
    </inertial>
    <visual>
      <origin
        xyz="0 0 0"
        rpy="0 0 0" />
      <geometry>
        <mesh
          filename="package://lide/meshes/LFW.STL" />
      </geometry>
      <material
        name="">
        <color
          rgba="0.898039215686275 0.917647058823529 0.929411764705882 1" />
      </material>
    </visual>
    <collision>
      <origin
        xyz="0 0 0"
        rpy="0 0 0" />
      <geometry>
        <mesh
          filename="package://lide/meshes/LFW.STL" />
      </geometry>
    </collision>
  </link>
  <joint
    name="LFW"
    type="continuous">
    <origin
      xyz="0.063346 -0.006798 0.015044"
      rpy="-1.6264 0 0" />
    <parent
      link="LFS" />
    <child
      link="LFW" />
    <axis
      xyz="1 0 0" />
    <limit
      effort="3.1"
      velocity="7" />
  </joint>
  <link
    name="RFS">
    <inertial>
      <origin
        xyz="-0.0191828308457407 -0.00900932874707057 0.0520056318885905"
        rpy="0 0 0" />
      <mass
        value="0.0727928435161986" />
      <inertia
        ixx="2.20927876796313E-05"
        ixy="-1.64845302056311E-08"
        ixz="1.56454773175212E-07"
        iyy="1.62632133784213E-05"
        iyz="-2.96411876510581E-09"
        izz="1.80843397531752E-05" />
    </inertial>
    <visual>
      <origin
        xyz="0 0 0"
        rpy="0 0 0" />
      <geometry>
        <mesh
          filename="package://lide/meshes/RFS.STL" />
      </geometry>
      <material
        name="">
        <color
          rgba="0.752941176470588 0.752941176470588 0.752941176470588 1" />
      </material>
    </visual>
    <collision>
      <origin
        xyz="0 0 0"
        rpy="0 0 0" />
      <geometry>
        <mesh
          filename="package://lide/meshes/RFS.STL" />
      </geometry>
    </collision>
  </link>
  <joint
    name="RFS"
    type="fixed">
    <origin
      xyz="-0.10807 -0.027781 -0.019216"
      rpy="1.5708 0 1.5708" />
    <parent
      link="base_link" />
    <child
      link="RFS" />
    <axis
      xyz="0 0 0" />
  </joint>
  <link
    name="RFW">
    <inertial>
      <origin
        xyz="-0.015 -3.46944695195361E-18 0"
        rpy="0 0 0" />
      <mass
        value="0.767080911081152" />
      <inertia
        ixx="0.00116426102407189"
        ixy="-4.9281223125782E-37"
        ixz="4.60638074444741E-39"
        iyy="0.000639661580367031"
        iyz="-5.25031148738029E-37"
        izz="0.000639661580367031" />
    </inertial>
    <visual>
      <origin
        xyz="0 0 0"
        rpy="0 0 0" />
      <geometry>
        <mesh
          filename="package://lide/meshes/RFW.STL" />
      </geometry>
      <material
        name="">
        <color
          rgba="0.898039215686275 0.917647058823529 0.929411764705882 1" />
      </material>
    </visual>
    <collision>
      <origin
        xyz="0 0 0"
        rpy="0 0 0" />
      <geometry>
        <mesh
          filename="package://lide/meshes/RFW.STL" />
      </geometry>
    </collision>
  </link>
  <joint
    name="RFW"
    type="continuous">
    <origin
      xyz="-0.036969 -0.024084 0.064073"
      rpy="0 0 0" />
    <parent
      link="RFS" />
    <child
      link="RFW" />
    <axis
      xyz="1 0 0" />
    <limit
      effort="3.1"
      velocity="7" />
  </joint>
  <link
    name="LBS">
    <inertial>
      <origin
        xyz="-4.7988246709707E-10 -0.0234733898228721 -1.16815021544703E-09"
        rpy="0 0 0" />
      <mass
        value="0.0835358720814331" />
      <inertia
        ixx="7.72968060896302E-05"
        ixy="-8.60478095936647E-13"
        ixz="1.40586689563478E-13"
        iyy="5.13820931926884E-05"
        iyz="-5.06559896290249E-12"
        izz="7.73952626484254E-05" />
    </inertial>
    <visual>
      <origin
        xyz="0 0 0"
        rpy="0 0 0" />
      <geometry>
        <mesh
          filename="package://lide/meshes/LBS.STL" />
      </geometry>
      <material
        name="">
        <color
          rgba="0.898039215686275 0.917647058823529 0.929411764705882 1" />
      </material>
    </visual>
    <collision>
      <origin
        xyz="0 0 0"
        rpy="0 0 0" />
      <geometry>
        <mesh
          filename="package://lide/meshes/LBS.STL" />
      </geometry>
    </collision>
  </link>
  <joint
    name="LBS"
    type="fixed">
    <origin
      xyz="-0.202 0.24575 -0.012562"
      rpy="1.5708 0 1.5708" />
    <parent
      link="base_link" />
    <child
      link="LBS" />
    <axis
      xyz="0 0 0" />
  </joint>
  <link
    name="LBW">
    <inertial>
      <origin
        xyz="0 0 -2.77555756156289E-17"
        rpy="0 0 0" />
      <mass
        value="0.299097213540614" />
      <inertia
        ixx="0.000107128427988291"
        ixy="-7.7154576721694E-22"
        ixz="-6.56176679301773E-22"
        iyy="0.000109833959413418"
        iyz="-8.63231614238912E-20"
        izz="0.000107128427988291" />
    </inertial>
    <visual>
      <origin
        xyz="0 0 0"
        rpy="0 0 0" />
      <geometry>
        <mesh
          filename="package://lide/meshes/LBW.STL" />
      </geometry>
      <material
        name="">
        <color
          rgba="0.898039215686275 0.917647058823529 0.929411764705882 1" />
      </material>
    </visual>
    <collision>
      <origin
        xyz="0 0 0"
        rpy="0 0 0" />
      <geometry>
        <mesh
          filename="package://lide/meshes/LBW.STL" />
      </geometry>
    </collision>
  </link>
  <joint
    name="LBW"
    type="fixed">
    <origin
      xyz="0 -0.055738 0"
      rpy="3.1416 0 1.5708" />
    <parent
      link="LBS" />
    <child
      link="LBW" />
    <axis
      xyz="0 0 0" />
  </joint>
  <link
    name="RBS">
    <inertial>
      <origin
        xyz="-4.79882529547115E-10 -0.0234733898228721 -1.16815021544703E-09"
        rpy="0 0 0" />
      <mass
        value="0.0835358720814328" />
      <inertia
        ixx="7.72968060896302E-05"
        ixy="-8.60478108781142E-13"
        ixz="1.40586703370834E-13"
        iyy="5.13820931926882E-05"
        iyz="-5.0655989562236E-12"
        izz="7.73952626484254E-05" />
    </inertial>
    <visual>
      <origin
        xyz="0 0 0"
        rpy="0 0 0" />
      <geometry>
        <mesh
          filename="package://lide/meshes/RBS.STL" />
      </geometry>
      <material
        name="">
        <color
          rgba="0.898039215686275 0.917647058823529 0.929411764705882 1" />
      </material>
    </visual>
    <collision>
      <origin
        xyz="0 0 0"
        rpy="0 0 0" />
      <geometry>
        <mesh
          filename="package://lide/meshes/RBS.STL" />
      </geometry>
    </collision>
  </link>
  <joint
    name="RBS"
    type="fixed">
    <origin
      xyz="-0.202 -0.07975 -0.012562"
      rpy="1.5708 0 1.5708" />
    <parent
      link="base_link" />
    <child
      link="RBS" />
    <axis
      xyz="0 0 0" />
  </joint>
  <link
    name="RBW">
    <inertial>
      <origin
        xyz="-6.93889390390723E-18 -6.93889390390723E-18 0"
        rpy="0 0 0" />
      <mass
        value="0.299097213540614" />
      <inertia
        ixx="0.000107128427988291"
        ixy="1.42968110446033E-21"
        ixz="-2.66815378385127E-22"
        iyy="0.000109833959413418"
        iyz="-8.63398373850403E-20"
        izz="0.000107128427988291" />
    </inertial>
    <visual>
      <origin
        xyz="0 0 0"
        rpy="0 0 0" />
      <geometry>
        <mesh
          filename="package://lide/meshes/RBW.STL" />
      </geometry>
      <material
        name="">
        <color
          rgba="0.898039215686275 0.917647058823529 0.929411764705882 1" />
      </material>
    </visual>
    <collision>
      <origin
        xyz="0 0 0"
        rpy="0 0 0" />
      <geometry>
        <mesh
          filename="package://lide/meshes/RBW.STL" />
      </geometry>
    </collision>
  </link>
  <joint
    name="RBW"
    type="fixed">
    <origin
      xyz="0 -0.055738 0"
      rpy="0 0 -1.5708" />
    <parent
      link="RBS" />
    <child
      link="RBW" />
    <axis
      xyz="0 0 0" />
  </joint>
  <link
    name="fcam">
    <inertial>
      <origin
        xyz="-0.0115544746517359 -2.64429642850283E-06 0.00129029302682174"
        rpy="0 0 0" />
      <mass
        value="0.0436119957238952" />
      <inertia
        ixx="2.35707061906175E-05"
        ixy="-1.01842273865751E-09"
        ixz="2.17585832536658E-08"
        iyy="4.29479050056035E-06"
        iyz="-8.8501811875944E-10"
        izz="2.21058153511886E-05" />
    </inertial>
    <visual>
      <origin
        xyz="0 0 0"
        rpy="0 0 0" />
      <geometry>
        <mesh
          filename="package://lide/meshes/fcam.STL" />
      </geometry>
      <material
        name="">
        <color
          rgba="0.792156862745098 0.819607843137255 0.933333333333333 1" />
      </material>
    </visual>
    <collision>
      <origin
        xyz="0 0 0"
        rpy="0 0 0" />
      <geometry>
        <mesh
          filename="package://lide/meshes/fcam.STL" />
      </geometry>
    </collision>
  </link>
  <joint
    name="fcam"
    type="fixed">
    <origin
      xyz="-0.0038823 0.083 0.12982"
      rpy="0 0.2618 0" />
    <parent
      link="base_link" />
    <child
      link="fcam" />
    <axis
      xyz="0 0 0" />
  </joint>
  <link
    name="bcam">
    <inertial>
      <origin
        xyz="-0.02010346452991 -2.64354903288522E-06 -0.00725869505663598"
        rpy="0 0 0" />
      <mass
        value="0.0436119949785286" />
      <inertia
        ixx="2.357070560996E-05"
        ixy="-1.01834758005627E-09"
        ixz="2.17579332532706E-08"
        iyy="4.29479078276665E-06"
        iyz="-8.85484503962029E-10"
        izz="2.21058144654638E-05" />
    </inertial>
    <visual>
      <origin
        xyz="0 0 0"
        rpy="0 0 0" />
      <geometry>
        <mesh
          filename="package://lide/meshes/bcam.STL" />
      </geometry>
      <material
        name="">
        <color
          rgba="0.792156862745098 0.819607843137255 0.933333333333333 1" />
      </material>
    </visual>
    <collision>
      <origin
        xyz="0 0 0"
        rpy="0 0 0" />
      <geometry>
        <mesh
          filename="package://lide/meshes/bcam.STL" />
      </geometry>
    </collision>
  </link>
  <joint
    name="bcam"
    type="fixed">
    <origin
      xyz="0 0.083 0.091232"
      rpy="0 0.7854 0" />
    <parent
      link="base_link" />
    <child
      link="bcam" />
    <axis
      xyz="0 0 0" />
  </joint>
  <link
    name="Lidar">
    <inertial>
      <origin
        xyz="0.0135233595886409 0.000461955982206344 -0.0287648854950511"
        rpy="0 0 0" />
      <mass
        value="0.0730845717569496" />
      <inertia
        ixx="1.95808757419765E-05"
        ixy="-1.03933585736234E-07"
        ixz="-4.28391168396098E-07"
        iyy="2.41250079666672E-05"
        iyz="9.42710206434157E-09"
        izz="4.14184516368183E-05" />
    </inertial>
    <visual>
      <origin
        xyz="0 0 0"
        rpy="0 0 0" />
      <geometry>
        <mesh
          filename="package://lide/meshes/Lidar.STL" />
      </geometry>
      <material
        name="">
        <color
          rgba="0.792156862745098 0.819607843137255 0.933333333333333 1" />
      </material>
    </visual>
    <collision>
      <origin
        xyz="0 0 0"
        rpy="0 0 0" />
      <geometry>
        <mesh
          filename="package://lide/meshes/Lidar.STL" />
      </geometry>
    </collision>
  </link>
  <joint
    name="Lidar"
    type="fixed">
    <origin
      xyz="-0.19458 0.082006 0.2065"
      rpy="0 0 0" />
    <parent
      link="base_link" />
    <child
      link="Lidar" />
    <axis
      xyz="0 0 0" />
  </joint>
  <link
    name="imu_link">
    <inertial>
      <origin
        xyz="0.00385022026093959 6.23984008056022E-05 -0.00103377575234337"
        rpy="0 0 0" />
      <mass
        value="0.00189180567975737" />
      <inertia
        ixx="7.79431263454135E-08"
        ixy="1.39214190556514E-10"
        ixz="1.54511633252899E-11"
        iyy="4.85473464623125E-08"
        iyz="-6.30099051334897E-11"
        izz="1.25233585370532E-07" />
    </inertial>
    <visual>
      <origin
        xyz="0 0 0"
        rpy="0 0 0" />
      <geometry>
        <mesh
          filename="package://lide/meshes/imu_link.STL" />
      </geometry>
      <material
        name="">
        <color
          rgba="0.898039215686275 0.917647058823529 0.929411764705882 1" />
      </material>
    </visual>
    <collision>
      <origin
        xyz="0 0 0"
        rpy="0 0 0" />
      <geometry>
        <mesh
          filename="package://lide/meshes/imu_link.STL" />
      </geometry>
    </collision>
  </link>
  <joint
    name="imu_link"
    type="fixed">
    <origin
      xyz="-0.044 0.083 0.155"
      rpy="0 0 0" />
    <parent
      link="base_link" />
    <child
      link="imu_link" />
    <axis
      xyz="0 0 0" />
  </joint>
</robot>